<?xml version="1.0"?>
<robot name="gripper">
  <link name="base_link">
    <visual>
      <origin xyz="0 0 0" rpy="1.57 0 0" />
      <geometry>
        <cylinder length="0.2" radius="0.2"/>
      </geometry>
    </visual>
  </link>

  <link name="right_proximal">
    <visual>
      <origin xyz="0.3 0.1 0" rpy="0 0 0" />
      <geometry>
        <box size="0.6 0.1 0.2"/>
      </geometry>
      <material name="c1">
        <color rgba="0 1 0 1" />
      </material>
    </visual>
  </link>

  <joint name="base_to_right_proximal" type="continuous">
    <parent link="base_link"/>
    <child link="right_proximal"/>
  </joint>

  <link name="right_distal">
    <visual>
      <origin xyz="0.3 0.05 0" rpy="0 0 0" />
      <geometry>
        <box size="0.6 0.1 0.2"/>
      </geometry>
      <material name="c1">
        <color rgba="1 0 0 1" />
      </material>
    </visual>
  </link>

  <joint name="right_proximal_to_right_distal" type="continuous">
    <origin xyz="0.6 0 0" rpy="0 0 0" />
    <parent link="right_proximal"/>
    <child link="right_distal"/>
  </joint>

</robot>